Workbook

Sheet Scenario
B2: Financial KPI and scenario model
B4: Case Selected: | C4: 1 | D4: =IF(C4=1,"Base",IF(C4=2,"Downside",IF(C4=3,"Upside","Invalid case"))) -> Base | G4: 1 Base 2 Downside 3 Upside
B5: Hypothetical next own fiscal year after FY2025. Not guidance, budget or actual FY2026.
B7: Selected result | C7: Visa | D7: Mastercard
B8: FY2025 baseline end | C8: ='Historical KPIs'!G10 -> 45930 | D8: ='Historical KPIs'!G48 -> 46022 | G8: Issuer | H8: FY2025 actual | I8: Selected scenario
B9: Hypothetical period end | C9: =DATE(YEAR(C8)+1,MONTH(C8),DAY(C8)) -> 46295 | D9: =DATE(YEAR(D8)+1,MONTH(D8),DAY(D8)) -> 46387 | G9: Visa | H9: =C31 -> 23994 | I9: =C37 -> 26400
B10: Scenario revenue (USDm) | C10: =C35 -> 44000 | D10: =D35 -> 36725.92 | G10: Mastercard | H10: =D31 -> 18897 | I10: =D37 -> 21301.034
B11: Scenario operating income (USDm) | C11: =C37 -> 26400 | D11: =D37 -> 21301.034
B12: Scenario operating margin | C12: =C38 -> 0.6 | D12: =D38 -> 0.58
B13: Op income change vs FY25 (USDm) | C13: =C39 -> 2406 | D13: =D39 -> 2404.0336
B14: Revenue change vs FY25 (USDm) | C14: =C40 -> 4000 | D14: =D40 -> 3934.92
B17: Editable assumptions
G18: Amber cells: edit assumptions.
B19: Revenue growth: Active Selection | C19: =IF(AND(ISNUMBER($C$4),OR($C$4=1,$C$4=2,$C$4=3)),IF(CHOOSE($C$4,ISNUMBER(C20),ISNUMBER(C21),ISNUMBER(C22)),IF(CHOOSE($C$4,C20,C21,C22)>=-1,CHOOSE($C$4,C20,C21,C22),"n.a."),"n.a."),"n.a.") -> 0.1 | D19: =IF(AND(ISNUMBER($C$4),OR($C$4=1,$C$4=2,$C$4=3)),IF(CHOOSE($C$4,ISNUMBER(D20),ISNUMBER(D21),ISNUMBER(D22)),IF(CHOOSE($C$4,D20,D21,D22)>=-1,CHOOSE($C$4,D20,D21,D22),"n.a."),"n.a."),"n.a.") -> 0.12 | G19: Active rows select one case.
B20: Base growth | C20: 0.1 | D20: 0.12 | G20: Costs are implied by revenue and margin.
B21: Downside growth | C21: 0.04 | D21: 0.06
B22: Upside growth | C22: 0.14 | D22: 0.16 | G22: Visa operating income (USDm)
G23: Growth across; margin down
B24: Operating margin: Active Selection | C24: =IF(AND(ISNUMBER($C$4),OR($C$4=1,$C$4=2,$C$4=3)),IF(CHOOSE($C$4,ISNUMBER(C25),ISNUMBER(C26),ISNUMBER(C27)),IF(AND(CHOOSE($C$4,C25,C26,C27)>=-1,CHOOSE($C$4,C25,C26,C27)<=1),CHOOSE($C$4,C25,C26,C27),"n.a."),"n.a."),"n.a.") -> 0.6 | D24: =IF(AND(ISNUMBER($C$4),OR($C$4=1,$C$4=2,$C$4=3)),IF(CHOOSE($C$4,ISNUMBER(D25),ISNUMBER(D26),ISNUMBER(D27)),IF(AND(CHOOSE($C$4,D25,D26,D27)>=-1,CHOOSE($C$4,D25,D26,D27)<=1),CHOOSE($C$4,D25,D26,D27),"n.a."),"n.a."),"n.a.") -> 0.58 | G24: =C37 -> 26400 | H24: =C21 -> 0.04 | I24: =C20 -> 0.1 | J24: =C22 -> 0.14
B25: Base margin | C25: 0.6 | D25: 0.58 | G25: =C26 -> 0.56 | H25: 23296 | I25: 24640 | J25: 25536
B26: Downside margin | C26: 0.56 | D26: 0.54 | G26: =C25 -> 0.6 | H26: 24960 | I26: 26400 | J26: 27360
B27: Upside margin | C27: 0.62 | D27: 0.6 | G27: =C27 -> 0.62 | H27: 25792 | I27: 27280 | J27: 28272
B29: Calculation (USD million)
B30: FY2025 net revenue | C30: ='Historical KPIs'!G12 -> 40000 | D30: ='Historical KPIs'!G50 -> 32791
B31: FY2025 operating income | C31: ='Historical KPIs'!G14 -> 23994 | D31: ='Historical KPIs'!G52 -> 18897
B32: FY2025 operating expenses | C32: ='Historical KPIs'!G13 -> 16006 | D32: ='Historical KPIs'!G51 -> 13894 | G32: Mastercard operating income (USDm)
B33: Revenue growth input | C33: =C19 -> 0.1 | D33: =D19 -> 0.12 | G33: Growth across; margin down
B34: Operating margin input | C34: =C24 -> 0.6 | D34: =D24 -> 0.58 | G34: =D37 -> 21301.034 | H34: =D21 -> 0.06 | I34: =D20 -> 0.12 | J34: =D22 -> 0.16
B35: Scenario revenue | C35: =IF(AND(ISNUMBER(C30),ISNUMBER(C33)),C30*(1+C33),"n.a.") -> 44000 | D35: =IF(AND(ISNUMBER(D30),ISNUMBER(D33)),D30*(1+D33),"n.a.") -> 36725.92 | G35: =D26 -> 0.54 | H35: 18769.568 | I35: 19831.997 | J35: 20540.282
B36: Scenario operating expenses | C36: =IF(AND(ISNUMBER(C35),ISNUMBER(C37)),C35-C37,"n.a.") -> 17600 | D36: =IF(AND(ISNUMBER(D35),ISNUMBER(D37)),D35-D37,"n.a.") -> 15424.886 | G36: =D25 -> 0.58 | H36: 20159.907 | I36: 21301.034 | J36: 22061.785
B37: Scenario operating income | C37: =IF(AND(ISNUMBER(C35),ISNUMBER(C34)),C35*C34,"n.a.") -> 26400 | D37: =IF(AND(ISNUMBER(D35),ISNUMBER(D34)),D35*D34,"n.a.") -> 21301.034 | G37: =D27 -> 0.6 | H37: 20855.076 | I37: 22035.552 | J37: 22822.536
B38: Scenario operating margin | C38: =IF(AND(ISNUMBER(C37),ISNUMBER(C35),C35>0),C37/C35,"n.a.") -> 0.6 | D38: =IF(AND(ISNUMBER(D37),ISNUMBER(D35),D35>0),D37/D35,"n.a.") -> 0.58
B39: Operating income change vs FY25 | C39: =IF(AND(ISNUMBER(C37),ISNUMBER(C31)),C37-C31,"n.a.") -> 2406 | D39: =IF(AND(ISNUMBER(D37),ISNUMBER(D31)),D37-D31,"n.a.") -> 2404.0336
B40: Revenue change vs FY25 | C40: =IF(AND(ISNUMBER(C35),ISNUMBER(C30)),C35-C30,"n.a.") -> 4000 | D40: =IF(AND(ISNUMBER(D35),ISNUMBER(D30)),D35-D30,"n.a.") -> 3934.92
B41: Operating income change (%) | C41: =IF(AND(ISNUMBER(C37),ISNUMBER(C31),C31>0),C37/C31-1,"n.a.") -> 0.10027507 | D41: =IF(AND(ISNUMBER(D37),ISNUMBER(D31),D31>0),D37/D31-1,"n.a.") -> 0.12721774
B42: Implied operating expense change (%) | C42: =IF(AND(ISNUMBER(C36),ISNUMBER(C32),C32>0),C36/C32-1,"n.a.") -> 0.099587655 | D42: =IF(AND(ISNUMBER(D36),ISNUMBER(D32),D32>0),D36/D32-1,"n.a.") -> 0.11018327 | G42: No scenario net income or cash flow is modeled.
G43: Changes compare a scenario with FY2025 actuals.
B44: Revenue - opex - op income | C44: =IF(AND(ISNUMBER(C35),ISNUMBER(C36),ISNUMBER(C37)),C35-C36-C37,"n.a.") -> 0 | D44: =IF(AND(ISNUMBER(D35),ISNUMBER(D36),ISNUMBER(D37)),D35-D36-D37,"n.a.") -> 0 | G44: They are not actual budget variances.
B45: Reconciliation tolerance (USDm) | C45: 0.01 | D45: 0.01

Sheet Historical KPIs
B2: Historical financial KPIs
B3: Reported fiscal years. Amounts in USD million; ratios are unscaled.
B5: Case Selected: | C5: ='Scenario'!D4 -> Base
B7: Visa reported fiscal years
B8: Fiscal year | C8: 2021 | D8: 2022 | E8: 2023 | F8: 2024 | G8: 2025
B9: Period start | C9: 2020-10-01T00:00:00.000Z | D9: 2021-10-01T00:00:00.000Z | E9: 2022-10-01T00:00:00.000Z | F9: 2023-10-01T00:00:00.000Z | G9: 2024-10-01T00:00:00.000Z
B10: Period end | C10: 2021-09-30T00:00:00.000Z | D10: 2022-09-30T00:00:00.000Z | E10: 2023-09-30T00:00:00.000Z | F10: 2024-09-30T00:00:00.000Z | G10: 2025-09-30T00:00:00.000Z
B12: Reported net revenue | C12: =IF(COUNTIFS('Actuals'!$K$6:$K$163,"visa|"&C$8&"|net_revenue")=1,IF(AND(COUNTIFS('Actuals'!$K$6:$K$163,"visa|"&C$8&"|net_revenue",'Actuals'!$F$6:$F$163,"<>")=1,ISNUMBER(_xlfn.XLOOKUP("visa|"&C$8&"|net_revenue",'Actuals'!$K$6:$K$163,'Actuals'!$F$6:$F$163,"n.a.",0)),_xlfn.XLOOKUP("visa|"&C$8&"|net_revenue",'Actuals'!$K$6:$K$163,'Actuals'!$G$6:$G$163,"n.a.",0)="USD"),_xlfn.XLOOKUP("visa|"&C$8&"|net_revenue",'Actuals'!$K$6:$K$163,'Actuals'!$F$6:$F$163,"n.a.",0)/1000000,"n.a."),"n.a.") -> 24105 | D12: =IF(COUNTIFS('Actuals'!$K$6:$K$163,"visa|"&D$8&"|net_revenue")=1,IF(AND(COUNTIFS('Actuals'!$K$6:$K$163,"visa|"&D$8&"|net_revenue",'Actuals'!$F$6:$F$163,"<>")=1,ISNUMBER(_xlfn.XLOOKUP("visa|"&D$8&"|net_revenue",'Actuals'!$K$6:$K$163,'Actuals'!$F$6:$F$163,"n.a.",0)),_xlfn.XLOOKUP("visa|"&D$8&"|net_revenue",'Actuals'!$K$6:$K$163,'Actuals'!$G$6:$G$163,"n.a.",0)="USD"),_xlfn.XLOOKUP("visa|"&D$8&"|net_revenue",'Actuals'!$K$6:$K$163,'Actuals'!$F$6:$F$163,"n.a.",0)/1000000,"n.a."),"n.a.") -> 29310 | E12: =IF(COUNTIFS('Actuals'!$K$6:$K$163,"visa|"&E$8&"|net_revenue")=1,IF(AND(COUNTIFS('Actuals'!$K$6:$K$163,"visa|"&E$8&"|net_revenue",'Actuals'!$F$6:$F$163,"<>")=1,ISNUMBER(_xlfn.XLOOKUP("visa|"&E$8&"|net_revenue",'Actuals'!$K$6:$K$163,'Actuals'!$F$6:$F$163,"n.a.",0)),_xlfn.XLOOKUP("visa|"&E$8&"|net_revenue",'Actuals'!$K$6:$K$163,'Actuals'!$G$6:$G$163,"n.a.",0)="USD"),_xlfn.XLOOKUP("visa|"&E$8&"|net_revenue",'Actuals'!$K$6:$K$163,'Actuals'!$F$6:$F$163,"n.a.",0)/1000000,"n.a."),"n.a.") -> 32653 | F12: =IF(COUNTIFS('Actuals'!$K$6:$K$163,"visa|"&F$8&"|net_revenue")=1,IF(AND(COUNTIFS('Actuals'!$K$6:$K$163,"visa|"&F$8&"|net_revenue",'Actuals'!$F$6:$F$163,"<>")=1,ISNUMBER(_xlfn.XLOOKUP("visa|"&F$8&"|net_revenue",'Actuals'!$K$6:$K$163,'Actuals'!$F$6:$F$163,"n.a.",0)),_xlfn.XLOOKUP("visa|"&F$8&"|net_revenue",'Actuals'!$K$6:$K$163,'Actuals'!$G$6:$G$163,"n.a.",0)="USD"),_xlfn.XLOOKUP("visa|"&F$8&"|net_revenue",'Actuals'!$K$6:$K$163,'Actuals'!$F$6:$F$163,"n.a.",0)/1000000,"n.a."),"n.a.") -> 35926 | G12: =IF(COUNTIFS('Actuals'!$K$6:$K$163,"visa|"&G$8&"|net_revenue")=1,IF(AND(COUNTIFS('Actuals'!$K$6:$K$163,"visa|"&G$8&"|net_revenue",'Actuals'!$F$6:$F$163,"<>")=1,ISNUMBER(_xlfn.XLOOKUP("visa|"&G$8&"|net_revenue",'Actuals'!$K$6:$K$163,'Actuals'!$F$6:$F$163,"n.a.",0)),_xlfn.XLOOKUP("visa|"&G$8&"|net_revenue",'Actuals'!$K$6:$K$163,'Actuals'!$G$6:$G$163,"n.a.",0)="USD"),_xlfn.XLOOKUP("visa|"&G$8&"|net_revenue",'Actuals'!$K$6:$K$163,'Actuals'!$F$6:$F$163,"n.a.",0)/1000000,"n.a."),"n.a.") -> 40000
B13: Reported operating expenses | C13: =IF(COUNTIFS('Actuals'!$K$6:$K$163,"visa|"&C$8&"|operating_expenses")=1,IF(AND(COUNTIFS('Actuals'!$K$6:$K$163,"visa|"&C$8&"|operating_expenses",'Actuals'!$F$6:$F$163,"<>")=1,ISNUMBER(_xlfn.XLOOKUP("visa|"&C$8&"|operating_expenses",'Actuals'!$K$6:$K$163,'Actuals'!$F$6:$F$163,"n.a.",0)),_xlfn.XLOOKUP("visa|"&C$8&"|operating_expenses",'Actuals'!$K$6:$K$163,'Actuals'!$G$6:$G$163,"n.a.",0)="USD"),_xlfn.XLOOKUP("visa|"&C$8&"|operating_expenses",'Actuals'!$K$6:$K$163,'Actuals'!$F$6:$F$163,"n.a.",0)/1000000,"n.a."),"n.a.") -> 8301 | D13: =IF(COUNTIFS('Actuals'!$K$6:$K$163,"visa|"&D$8&"|operating_expenses")=1,IF(AND(COUNTIFS('Actuals'!$K$6:$K$163,"visa|"&D$8&"|operating_expenses",'Actuals'!$F$6:$F$163,"<>")=1,ISNUMBER(_xlfn.XLOOKUP("visa|"&D$8&"|operating_expenses",'Actuals'!$K$6:$K$163,'Actuals'!$F$6:$F$163,"n.a.",0)),_xlfn.XLOOKUP("visa|"&D$8&"|operating_expenses",'Actuals'!$K$6:$K$163,'Actuals'!$G$6:$G$163,"n.a.",0)="USD"),_xlfn.XLOOKUP("visa|"&D$8&"|operating_expenses",'Actuals'!$K$6:$K$163,'Actuals'!$F$6:$F$163,"n.a.",0)/1000000,"n.a."),"n.a.") -> 10497 | E13: =IF(COUNTIFS('Actuals'!$K$6:$K$163,"visa|"&E$8&"|operating_expenses")=1,IF(AND(COUNTIFS('Actuals'!$K$6:$K$163,"visa|"&E$8&"|operating_expenses",'Actuals'!$F$6:$F$163,"<>")=1,ISNUMBER(_xlfn.XLOOKUP("visa|"&E$8&"|operating_expenses",'Actuals'!$K$6:$K$163,'Actuals'!$F$6:$F$163,"n.a.",0)),_xlfn.XLOOKUP("visa|"&E$8&"|operating_expenses",'Actuals'!$K$6:$K$163,'Actuals'!$G$6:$G$163,"n.a.",0)="USD"),_xlfn.XLOOKUP("visa|"&E$8&"|operating_expenses",'Actuals'!$K$6:$K$163,'Actuals'!$F$6:$F$163,"n.a.",0)/1000000,"n.a."),"n.a.") -> 11653 | F13: =IF(COUNTIFS('Actuals'!$K$6:$K$163,"visa|"&F$8&"|operating_expenses")=1,IF(AND(COUNTIFS('Actuals'!$K$6:$K$163,"visa|"&F$8&"|operating_expenses",'Actuals'!$F$6:$F$163,"<>")=1,ISNUMBER(_xlfn.XLOOKUP("visa|"&F$8&"|operating_expenses",'Actuals'!$K$6:$K$163,'Actuals'!$F$6:$F$163,"n.a.",0)),_xlfn.XLOOKUP("visa|"&F$8&"|operating_expenses",'Actuals'!$K$6:$K$163,'Actuals'!$G$6:$G$163,"n.a.",0)="USD"),_xlfn.XLOOKUP("visa|"&F$8&"|operating_expenses",'Actuals'!$K$6:$K$163,'Actuals'!$F$6:$F$163,"n.a.",0)/1000000,"n.a."),"n.a.") -> 12331 | G13: =IF(COUNTIFS('Actuals'!$K$6:$K$163,"visa|"&G$8&"|operating_expenses")=1,IF(AND(COUNTIFS('Actuals'!$K$6:$K$163,"visa|"&G$8&"|operating_expenses",'Actuals'!$F$6:$F$163,"<>")=1,ISNUMBER(_xlfn.XLOOKUP("visa|"&G$8&"|operating_expenses",'Actuals'!$K$6:$K$163,'Actuals'!$F$6:$F$163,"n.a.",0)),_xlfn.XLOOKUP("visa|"&G$8&"|operating_expenses",'Actuals'!$K$6:$K$163,'Actuals'!$G$6:$G$163,"n.a.",0)="USD"),_xlfn.XLOOKUP("visa|"&G$8&"|operating_expenses",'Actuals'!$K$6:$K$163,'Actuals'!$F$6:$F$163,"n.a.",0)/1000000,"n.a."),"n.a.") -> 16006
B14: Reported operating income | C14: =IF(COUNTIFS('Actuals'!$K$6:$K$163,"visa|"&C$8&"|operating_income")=1,IF(AND(COUNTIFS('Actuals'!$K$6:$K$163,"visa|"&C$8&"|operating_income",'Actuals'!$F$6:$F$163,"<>")=1,ISNUMBER(_xlfn.XLOOKUP("visa|"&C$8&"|operating_income",'Actuals'!$K$6:$K$163,'Actuals'!$F$6:$F$163,"n.a.",0)),_xlfn.XLOOKUP("visa|"&C$8&"|operating_income",'Actuals'!$K$6:$K$163,'Actuals'!$G$6:$G$163,"n.a.",0)="USD"),_xlfn.XLOOKUP("visa|"&C$8&"|operating_income",'Actuals'!$K$6:$K$163,'Actuals'!$F$6:$F$163,"n.a.",0)/1000000,"n.a."),"n.a.") -> 15804 | D14: =IF(COUNTIFS('Actuals'!$K$6:$K$163,"visa|"&D$8&"|operating_income")=1,IF(AND(COUNTIFS('Actuals'!$K$6:$K$163,"visa|"&D$8&"|operating_income",'Actuals'!$F$6:$F$163,"<>")=1,ISNUMBER(_xlfn.XLOOKUP("visa|"&D$8&"|operating_income",'Actuals'!$K$6:$K$163,'Actuals'!$F$6:$F$163,"n.a.",0)),_xlfn.XLOOKUP("visa|"&D$8&"|operating_income",'Actuals'!$K$6:$K$163,'Actuals'!$G$6:$G$163,"n.a.",0)="USD"),_xlfn.XLOOKUP("visa|"&D$8&"|operating_income",'Actuals'!$K$6:$K$163,'Actuals'!$F$6:$F$163,"n.a.",0)/1000000,"n.a."),"n.a.") -> 18813 | E14: =IF(COUNTIFS('Actuals'!$K$6:$K$163,"visa|"&E$8&"|operating_income")=1,IF(AND(COUNTIFS('Actuals'!$K$6:$K$163,"visa|"&E$8&"|operating_income",'Actuals'!$F$6:$F$163,"<>")=1,ISNUMBER(_xlfn.XLOOKUP("visa|"&E$8&"|operating_income",'Actuals'!$K$6:$K$163,'Actuals'!$F$6:$F$163,"n.a.",0)),_xlfn.XLOOKUP("visa|"&E$8&"|operating_income",'Actuals'!$K$6:$K$163,'Actuals'!$G$6:$G$163,"n.a.",0)="USD"),_xlfn.XLOOKUP("visa|"&E$8&"|operating_income",'Actuals'!$K$6:$K$163,'Actuals'!$F$6:$F$163,"n.a.",0)/1000000,"n.a."),"n.a.") -> 21000 | F14: =IF(COUNTIFS('Actuals'!$K$6:$K$163,"visa|"&F$8&"|operating_income")=1,IF(AND(COUNTIFS('Actuals'!$K$6:$K$163,"visa|"&F$8&"|operating_income",'Actuals'!$F$6:$F$163,"<>")=1,ISNUMBER(_xlfn.XLOOKUP("visa|"&F$8&"|operating_income",'Actuals'!$K$6:$K$163,'Actuals'!$F$6:$F$163,"n.a.",0)),_xlfn.XLOOKUP("visa|"&F$8&"|operating_income",'Actuals'!$K$6:$K$163,'Actuals'!$G$6:$G$163,"n.a.",0)="USD"),_xlfn.XLOOKUP("visa|"&F$8&"|operating_income",'Actuals'!$K$6:$K$163,'Actuals'!$F$6:$F$163,"n.a.",0)/1000000,"n.a."),"n.a.") -> 23595 | G14: =IF(COUNTIFS('Actuals'!$K$6:$K$163,"visa|"&G$8&"|operating_income")=1,IF(AND(COUNTIFS('Actuals'!$K$6:$K$163,"visa|"&G$8&"|operating_income",'Actuals'!$F$6:$F$163,"<>")=1,ISNUMBER(_xlfn.XLOOKUP("visa|"&G$8&"|operating_income",'Actuals'!$K$6:$K$163,'Actuals'!$F$6:$F$163,"n.a.",0)),_xlfn.XLOOKUP("visa|"&G$8&"|operating_income",'Actuals'!$K$6:$K$163,'Actuals'!$G$6:$G$163,"n.a.",0)="USD"),_xlfn.XLOOKUP("visa|"&G$8&"|operating_income",'Actuals'!$K$6:$K$163,'Actuals'!$F$6:$F$163,"n.a.",0)/1000000,"n.a."),"n.a.") -> 23994
B15: Reported consolidated net income | C15: =IF(COUNTIFS('Actuals'!$K$6:$K$163,"visa|"&C$8&"|net_income")=1,IF(AND(COUNTIFS('Actuals'!$K$6:$K$163,"visa|"&C$8&"|net_income",'Actuals'!$F$6:$F$163,"<>")=1,ISNUMBER(_xlfn.XLOOKUP("visa|"&C$8&"|net_income",'Actuals'!$K$6:$K$163,'Actuals'!$F$6:$F$163,"n.a.",0)),_xlfn.XLOOKUP("visa|"&C$8&"|net_income",'Actuals'!$K$6:$K$163,'Actuals'!$G$6:$G$163,"n.a.",0)="USD"),_xlfn.XLOOKUP("visa|"&C$8&"|net_income",'Actuals'!$K$6:$K$163,'Actuals'!$F$6:$F$163,"n.a.",0)/1000000,"n.a."),"n.a.") -> 12311 | D15: =IF(COUNTIFS('Actuals'!$K$6:$K$163,"visa|"&D$8&"|net_income")=1,IF(AND(COUNTIFS('Actuals'!$K$6:$K$163,"visa|"&D$8&"|net_income",'Actuals'!$F$6:$F$163,"<>")=1,ISNUMBER(_xlfn.XLOOKUP("visa|"&D$8&"|net_income",'Actuals'!$K$6:$K$163,'Actuals'!$F$6:$F$163,"n.a.",0)),_xlfn.XLOOKUP("visa|"&D$8&"|net_income",'Actuals'!$K$6:$K$163,'Actuals'!$G$6:$G$163,"n.a.",0)="USD"),_xlfn.XLOOKUP("visa|"&D$8&"|net_income",'Actuals'!$K$6:$K$163,'Actuals'!$F$6:$F$163,"n.a.",0)/1000000,"n.a."),"n.a.") -> 14957 | E15: =IF(COUNTIFS('Actuals'!$K$6:$K$163,"visa|"&E$8&"|net_income")=1,IF(AND(COUNTIFS('Actuals'!$K$6:$K$163,"visa|"&E$8&"|net_income",'Actuals'!$F$6:$F$163,"<>")=1,ISNUMBER(_xlfn.XLOOKUP("visa|"&E$8&"|net_income",'Actuals'!$K$6:$K$163,'Actuals'!$F$6:$F$163,"n.a.",0)),_xlfn.XLOOKUP("visa|"&E$8&"|net_income",'Actuals'!$K$6:$K$163,'Actuals'!$G$6:$G$163,"n.a.",0)="USD"),_xlfn.XLOOKUP("visa|"&E$8&"|net_income",'Actuals'!$K$6:$K$163,'Actuals'!$F$6:$F$163,"n.a.",0)/1000000,"n.a."),"n.a.") -> 17273 | F15: =IF(COUNTIFS('Actuals'!$K$6:$K$163,"visa|"&F$8&"|net_income")=1,IF(AND(COUNTIFS('Actuals'!$K$6:$K$163,"visa|"&F$8&"|net_income",'Actuals'!$F$6:$F$163,"<>")=1,ISNUMBER(_xlfn.XLOOKUP("visa|"&F$8&"|net_income",'Actuals'!$K$6:$K$163,'Actuals'!$F$6:$F$163,"n.a.",0)),_xlfn.XLOOKUP("visa|"&F$8&"|net_income",'Actuals'!$K$6:$K$163,'Actuals'!$G$6:$G$163,"n.a.",0)="USD"),_xlfn.XLOOKUP("visa|"&F$8&"|net_income",'Actuals'!$K$6:$K$163,'Actuals'!$F$6:$F$163,"n.a.",0)/1000000,"n.a."),"n.a.") -> 19743 | G15: =IF(COUNTIFS('Actuals'!$K$6:$K$163,"visa|"&G$8&"|net_income")=1,IF(AND(COUNTIFS('Actuals'!$K$6:$K$163,"visa|"&G$8&"|net_income",'Actuals'!$F$6:$F$163,"<>")=1,ISNUMBER(_xlfn.XLOOKUP("visa|"&G$8&"|net_income",'Actuals'!$K$6:$K$163,'Actuals'!$F$6:$F$163,"n.a.",0)),_xlfn.XLOOKUP("visa|"&G$8&"|net_income",'Actuals'!$K$6:$K$163,'Actuals'!$G$6:$G$163,"n.a.",0)="USD"),_xlfn.XLOOKUP("visa|"&G$8&"|net_income",'Actuals'!$K$6:$K$163,'Actuals'!$F$6:$F$163,"n.a.",0)/1000000,"n.a."),"n.a.") -> 20058
B16: Reported operating cash flow | C16: =IF(COUNTIFS('Actuals'!$K$6:$K$163,"visa|"&C$8&"|operating_cash_flow")=1,IF(AND(COUNTIFS('Actuals'!$K$6:$K$163,"visa|"&C$8&"|operating_cash_flow",'Actuals'!$F$6:$F$163,"<>")=1,ISNUMBER(_xlfn.XLOOKUP("visa|"&C$8&"|operating_cash_flow",'Actuals'!$K$6:$K$163,'Actuals'!$F$6:$F$163,"n.a.",0)),_xlfn.XLOOKUP("visa|"&C$8&"|operating_cash_flow",'Actuals'!$K$6:$K$163,'Actuals'!$G$6:$G$163,"n.a.",0)="USD"),_xlfn.XLOOKUP("visa|"&C$8&"|operating_cash_flow",'Actuals'!$K$6:$K$163,'Actuals'!$F$6:$F$163,"n.a.",0)/1000000,"n.a."),"n.a.") -> 15227 | D16: =IF(COUNTIFS('Actuals'!$K$6:$K$163,"visa|"&D$8&"|operating_cash_flow")=1,IF(AND(COUNTIFS('Actuals'!$K$6:$K$163,"visa|"&D$8&"|operating_cash_flow",'Actuals'!$F$6:$F$163,"<>")=1,ISNUMBER(_xlfn.XLOOKUP("visa|"&D$8&"|operating_cash_flow",'Actuals'!$K$6:$K$163,'Actuals'!$F$6:$F$163,"n.a.",0)),_xlfn.XLOOKUP("visa|"&D$8&"|operating_cash_flow",'Actuals'!$K$6:$K$163,'Actuals'!$G$6:$G$163,"n.a.",0)="USD"),_xlfn.XLOOKUP("visa|"&D$8&"|operating_cash_flow",'Actuals'!$K$6:$K$163,'Actuals'!$F$6:$F$163,"n.a.",0)/1000000,"n.a."),"n.a.") -> 18849 | E16: =IF(COUNTIFS('Actuals'!$K$6:$K$163,"visa|"&E$8&"|operating_cash_flow")=1,IF(AND(COUNTIFS('Actuals'!$K$6:$K$163,"visa|"&E$8&"|operating_cash_flow",'Actuals'!$F$6:$F$163,"<>")=1,ISNUMBER(_xlfn.XLOOKUP("visa|"&E$8&"|operating_cash_flow",'Actuals'!$K$6:$K$163,'Actuals'!$F$6:$F$163,"n.a.",0)),_xlfn.XLOOKUP("visa|"&E$8&"|operating_cash_flow",'Actuals'!$K$6:$K$163,'Actuals'!$G$6:$G$163,"n.a.",0)="USD"),_xlfn.XLOOKUP("visa|"&E$8&"|operating_cash_flow",'Actuals'!$K$6:$K$163,'Actuals'!$F$6:$F$163,"n.a.",0)/1000000,"n.a."),"n.a.") -> 20755 | F16: =IF(COUNTIFS('Actuals'!$K$6:$K$163,"visa|"&F$8&"|operating_cash_flow")=1,IF(AND(COUNTIFS('Actuals'!$K$6:$K$163,"visa|"&F$8&"|operating_cash_flow",'Actuals'!$F$6:$F$163,"<>")=1,ISNUMBER(_xlfn.XLOOKUP("visa|"&F$8&"|operating_cash_flow",'Actuals'!$K$6:$K$163,'Actuals'!$F$6:$F$163,"n.a.",0)),_xlfn.XLOOKUP("visa|"&F$8&"|operating_cash_flow",'Actuals'!$K$6:$K$163,'Actuals'!$G$6:$G$163,"n.a.",0)="USD"),_xlfn.XLOOKUP("visa|"&F$8&"|operating_cash_flow",'Actuals'!$K$6:$K$163,'Actuals'!$F$6:$F$163,"n.a.",0)/1000000,"n.a."),"n.a.") -> 19950 | G16: =IF(COUNTIFS('Actuals'!$K$6:$K$163,"visa|"&G$8&"|operating_cash_flow")=1,IF(AND(COUNTIFS('Actuals'!$K$6:$K$163,"visa|"&G$8&"|operating_cash_flow",'Actuals'!$F$6:$F$163,"<>")=1,ISNUMBER(_xlfn.XLOOKUP("visa|"&G$8&"|operating_cash_flow",'Actuals'!$K$6:$K$163,'Actuals'!$F$6:$F$163,"n.a.",0)),_xlfn.XLOOKUP("visa|"&G$8&"|operating_cash_flow",'Actuals'!$K$6:$K$163,'Actuals'!$G$6:$G$163,"n.a.",0)="USD"),_xlfn.XLOOKUP("visa|"&G$8&"|operating_cash_flow",'Actuals'!$K$6:$K$163,'Actuals'!$F$6:$F$163,"n.a.",0)/1000000,"n.a."),"n.a.") -> 23059
B17: Cash and cash equivalents | C17: =IF(COUNTIFS('Actuals'!$K$6:$K$163,"visa|"&C$8&"|cash_and_cash_equivalents")=1,IF(AND(COUNTIFS('Actuals'!$K$6:$K$163,"visa|"&C$8&"|cash_and_cash_equivalents",'Actuals'!$F$6:$F$163,"<>")=1,ISNUMBER(_xlfn.XLOOKUP("visa|"&C$8&"|cash_and_cash_equivalents",'Actuals'!$K$6:$K$163,'Actuals'!$F$6:$F$163,"n.a.",0)),_xlfn.XLOOKUP("visa|"&C$8&"|cash_and_cash_equivalents",'Actuals'!$K$6:$K$163,'Actuals'!$G$6:$G$163,"n.a.",0)="USD"),_xlfn.XLOOKUP("visa|"&C$8&"|cash_and_cash_equivalents",'Actuals'!$K$6:$K$163,'Actuals'!$F$6:$F$163,"n.a.",0)/1000000,"n.a."),"n.a.") -> 16487 | D17: =IF(COUNTIFS('Actuals'!$K$6:$K$163,"visa|"&D$8&"|cash_and_cash_equivalents")=1,IF(AND(COUNTIFS('Actuals'!$K$6:$K$163,"visa|"&D$8&"|cash_and_cash_equivalents",'Actuals'!$F$6:$F$163,"<>")=1,ISNUMBER(_xlfn.XLOOKUP("visa|"&D$8&"|cash_and_cash_equivalents",'Actuals'!$K$6:$K$163,'Actuals'!$F$6:$F$163,"n.a.",0)),_xlfn.XLOOKUP("visa|"&D$8&"|cash_and_cash_equivalents",'Actuals'!$K$6:$K$163,'Actuals'!$G$6:$G$163,"n.a.",0)="USD"),_xlfn.XLOOKUP("visa|"&D$8&"|cash_and_cash_equivalents",'Actuals'!$K$6:$K$163,'Actuals'!$F$6:$F$163,"n.a.",0)/1000000,"n.a."),"n.a.") -> 15689 | E17: =IF(COUNTIFS('Actuals'!$K$6:$K$163,"visa|"&E$8&"|cash_and_cash_equivalents")=1,IF(AND(COUNTIFS('Actuals'!$K$6:$K$163,"visa|"&E$8&"|cash_and_cash_equivalents",'Actuals'!$F$6:$F$163,"<>")=1,ISNUMBER(_xlfn.XLOOKUP("visa|"&E$8&"|cash_and_cash_equivalents",'Actuals'!$K$6:$K$163,'Actuals'!$F$6:$F$163,"n.a.",0)),_xlfn.XLOOKUP("visa|"&E$8&"|cash_and_cash_equivalents",'Actuals'!$K$6:$K$163,'Actuals'!$G$6:$G$163,"n.a.",0)="USD"),_xlfn.XLOOKUP("visa|"&E$8&"|cash_and_cash_equivalents",'Actuals'!$K$6:$K$163,'Actuals'!$F$6:$F$163,"n.a.",0)/1000000,"n.a."),"n.a.") -> 16286 | F17: =IF(COUNTIFS('Actuals'!$K$6:$K$163,"visa|"&F$8&"|cash_and_cash_equivalents")=1,IF(AND(COUNTIFS('Actuals'!$K$6:$K$163,"visa|"&F$8&"|cash_and_cash_equivalents",'Actuals'!$F$6:$F$163,"<>")=1,ISNUMBER(_xlfn.XLOOKUP("visa|"&F$8&"|cash_and_cash_equivalents",'Actuals'!$K$6:$K$163,'Actuals'!$F$6:$F$163,"n.a.",0)),_xlfn.XLOOKUP("visa|"&F$8&"|cash_and_cash_equivalents",'Actuals'!$K$6:$K$163,'Actuals'!$G$6:$G$163,"n.a.",0)="USD"),_xlfn.XLOOKUP("visa|"&F$8&"|cash_and_cash_equivalents",'Actuals'!$K$6:$K$163,'Actuals'!$F$6:$F$163,"n.a.",0)/1000000,"n.a."),"n.a.") -> 11975 | G17: =IF(COUNTIFS('Actuals'!$K$6:$K$163,"visa|"&G$8&"|cash_and_cash_equivalents")=1,IF(AND(COUNTIFS('Actuals'!$K$6:$K$163,"visa|"&G$8&"|cash_and_cash_equivalents",'Actuals'!$F$6:$F$163,"<>")=1,ISNUMBER(_xlfn.XLOOKUP("visa|"&G$8&"|cash_and_cash_equivalents",'Actuals'!$K$6:$K$163,'Actuals'!$F$6:$F$163,"n.a.",0)),_xlfn.XLOOKUP("visa|"&G$8&"|cash_and_cash_equivalents",'Actuals'!$K$6:$K$163,'Actuals'!$G$6:$G$163,"n.a.",0)="USD"),_xlfn.XLOOKUP("visa|"&G$8&"|cash_and_cash_equivalents",'Actuals'!$K$6:$K$163,'Actuals'!$F$6:$F$163,"n.a.",0)/1000000,"n.a."),"n.a.") -> 17164
B18: Current debt carrying amount | C18: =IF(COUNTIFS('Actuals'!$K$6:$K$163,"visa|"&C$8&"|current_debt")=1,IF(AND(COUNTIFS('Actuals'!$K$6:$K$163,"visa|"&C$8&"|current_debt",'Actuals'!$F$6:$F$163,"<>")=1,ISNUMBER(_xlfn.XLOOKUP("visa|"&C$8&"|current_debt",'Actuals'!$K$6:$K$163,'Actuals'!$F$6:$F$163,"n.a.",0)),_xlfn.XLOOKUP("visa|"&C$8&"|current_debt",'Actuals'!$K$6:$K$163,'Actuals'!$G$6:$G$163,"n.a.",0)="USD"),_xlfn.XLOOKUP("visa|"&C$8&"|current_debt",'Actuals'!$K$6:$K$163,'Actuals'!$F$6:$F$163,"n.a.",0)/1000000,"n.a."),"n.a.") -> 999 | D18: =IF(COUNTIFS('Actuals'!$K$6:$K$163,"visa|"&D$8&"|current_debt")=1,IF(AND(COUNTIFS('Actuals'!$K$6:$K$163,"visa|"&D$8&"|current_debt",'Actuals'!$F$6:$F$163,"<>")=1,ISNUMBER(_xlfn.XLOOKUP("visa|"&D$8&"|current_debt",'Actuals'!$K$6:$K$163,'Actuals'!$F$6:$F$163,"n.a.",0)),_xlfn.XLOOKUP("visa|"&D$8&"|current_debt",'Actuals'!$K$6:$K$163,'Actuals'!$G$6:$G$163,"n.a.",0)="USD"),_xlfn.XLOOKUP("visa|"&D$8&"|current_debt",'Actuals'!$K$6:$K$163,'Actuals'!$F$6:$F$163,"n.a.",0)/1000000,"n.a."),"n.a.") -> 2250 | E18: =IF(COUNTIFS('Actuals'!$K$6:$K$163,"visa|"&E$8&"|current_debt")=1,IF(AND(COUNTIFS('Actuals'!$K$6:$K$163,"visa|"&E$8&"|current_debt",'Actuals'!$F$6:$F$163,"<>")=1,ISNUMBER(_xlfn.XLOOKUP("visa|"&E$8&"|current_debt",'Actuals'!$K$6:$K$163,'Actuals'!$F$6:$F$163,"n.a.",0)),_xlfn.XLOOKUP("visa|"&E$8&"|current_debt",'Actuals'!$K$6:$K$163,'Actuals'!$G$6:$G$163,"n.a.",0)="USD"),_xlfn.XLOOKUP("visa|"&E$8&"|current_debt",'Actuals'!$K$6:$K$163,'Actuals'!$F$6:$F$163,"n.a.",0)/1000000,"n.a."),"n.a.") -> 0 | F18: =IF(COUNTIFS('Actuals'!$K$6:$K$163,"visa|"&F$8&"|current_debt")=1,IF(AND(COUNTIFS('Actuals'!$K$6:$K$163,"visa|"&F$8&"|current_debt",'Actuals'!$F$6:$F$163,"<>")=1,ISNUMBER(_xlfn.XLOOKUP("visa|"&F$8&"|current_debt",'Actuals'!$K$6:$K$163,'Actuals'!$F$6:$F$163,"n.a.",0)),_xlfn.XLOOKUP("visa|"&F$8&"|current_debt",'Actuals'!$K$6:$K$163,'Actuals'!$G$6:$G$163,"n.a.",0)="USD"),_xlfn.XLOOKUP("visa|"&F$8&"|current_debt",'Actuals'!$K$6:$K$163,'Actuals'!$F$6:$F$163,"n.a.",0)/1000000,"n.a."),"n.a.") -> 0 | G18: =IF(COUNTIFS('Actuals'!$K$6:$K$163,"visa|"&G$8&"|current_debt")=1,IF(AND(COUNTIFS('Actuals'!$K$6:$K$163,"visa|"&G$8&"|current_debt",'Actuals'!$F$6:$F$163,"<>")=1,ISNUMBER(_xlfn.XLOOKUP("visa|"&G$8&"|current_debt",'Actuals'!$K$6:$K$163,'Actuals'!$F$6:$F$163,"n.a.",0)),_xlfn.XLOOKUP("visa|"&G$8&"|current_debt",'Actuals'!$K$6:$K$163,'Actuals'!$G$6:$G$163,"n.a.",0)="USD"),_xlfn.XLOOKUP("visa|"&G$8&"|current_debt",'Actuals'!$K$6:$K$163,'Actuals'!$F$6:$F$163,"n.a.",0)/1000000,"n.a."),"n.a.") -> 5569
B19: Noncurrent debt carrying amount | C19: =IF(COUNTIFS('Actuals'!$K$6:$K$163,"visa|"&C$8&"|noncurrent_debt")=1,IF(AND(COUNTIFS('Actuals'!$K$6:$K$163,"visa|"&C$8&"|noncurrent_debt",'Actuals'!$F$6:$F$163,"<>")=1,ISNUMBER(_xlfn.XLOOKUP("visa|"&C$8&"|noncurrent_debt",'Actuals'!$K$6:$K$163,'Actuals'!$F$6:$F$163,"n.a.",0)),_xlfn.XLOOKUP("visa|"&C$8&"|noncurrent_debt",'Actuals'!$K$6:$K$163,'Actuals'!$G$6:$G$163,"n.a.",0)="USD"),_xlfn.XLOOKUP("visa|"&C$8&"|noncurrent_debt",'Actuals'!$K$6:$K$163,'Actuals'!$F$6:$F$163,"n.a.",0)/1000000,"n.a."),"n.a.") -> 19978 | D19: =IF(COUNTIFS('Actuals'!$K$6:$K$163,"visa|"&D$8&"|noncurrent_debt")=1,IF(AND(COUNTIFS('Actuals'!$K$6:$K$163,"visa|"&D$8&"|noncurrent_debt",'Actuals'!$F$6:$F$163,"<>")=1,ISNUMBER(_xlfn.XLOOKUP("visa|"&D$8&"|noncurrent_debt",'Actuals'!$K$6:$K$163,'Actuals'!$F$6:$F$163,"n.a.",0)),_xlfn.XLOOKUP("visa|"&D$8&"|noncurrent_debt",'Actuals'!$K$6:$K$163,'Actuals'!$G$6:$G$163,"n.a.",0)="USD"),_xlfn.XLOOKUP("visa|"&D$8&"|noncurrent_debt",'Actuals'!$K$6:$K$163,'Actuals'!$F$6:$F$163,"n.a.",0)/1000000,"n.a."),"n.a.") -> 20200 | E19: =IF(COUNTIFS('Actuals'!$K$6:$K$163,"visa|"&E$8&"|noncurrent_debt")=1,IF(AND(COUNTIFS('Actuals'!$K$6:$K$163,"visa|"&E$8&"|noncurrent_debt",'Actuals'!$F$6:$F$163,"<>")=1,ISNUMBER(_xlfn.XLOOKUP("visa|"&E$8&"|noncurrent_debt",'Actuals'!$K$6:$K$163,'Actuals'!$F$6:$F$163,"n.a.",0)),_xlfn.XLOOKUP("visa|"&E$8&"|noncurrent_debt",'Actuals'!$K$6:$K$163,'Actuals'!$G$6:$G$163,"n.a.",0)="USD"),_xlfn.XLOOKUP("visa|"&E$8&"|noncurrent_debt",'Actuals'!$K$6:$K$163,'Actuals'!$F$6:$F$163,"n.a.",0)/1000000,"n.a."),"n.a.") -> 20463 | F19: =IF(COUNTIFS('Actuals'!$K$6:$K$163,"visa|"&F$8&"|noncurrent_debt")=1,IF(AND(COUNTIFS('Actuals'!$K$6:$K$163,"visa|"&F$8&"|noncurrent_debt",'Actuals'!$F$6:$F$163,"<>")=1,ISNUMBER(_xlfn.XLOOKUP("visa|"&F$8&"|noncurrent_debt",'Actuals'!$K$6:$K$163,'Actuals'!$F$6:$F$163,"n.a.",0)),_xlfn.XLOOKUP("visa|"&F$8&"|noncurrent_debt",'Actuals'!$K$6:$K$163,'Actuals'!$G$6:$G$163,"n.a.",0)="USD"),_xlfn.XLOOKUP("visa|"&F$8&"|noncurrent_debt",'Actuals'!$K$6:$K$163,'Actuals'!$F$6:$F$163,"n.a.",0)/1000000,"n.a."),"n.a.") -> 20836 | G19: =IF(COUNTIFS('Actuals'!$K$6:$K$163,"visa|"&G$8&"|noncurrent_debt")=1,IF(AND(COUNTIFS('Actuals'!$K$6:$K$163,"visa|"&G$8&"|noncurrent_debt",'Actuals'!$F$6:$F$163,"<>")=1,ISNUMBER(_xlfn.XLOOKUP("visa|"&G$8&"|noncurrent_debt",'Actuals'!$K$6:$K$163,'Actuals'!$F$6:$F$163,"n.a.",0)),_xlfn.XLOOKUP("visa|"&G$8&"|noncurrent_debt",'Actuals'!$K$6:$K$163,'Actuals'!$G$6:$G$163,"n.a.",0)="USD"),_xlfn.XLOOKUP("visa|"&G$8&"|noncurrent_debt",'Actuals'!$K$6:$K$163,'Actuals'!$F$6:$F$163,"n.a.",0)/1000000,"n.a."),"n.a.") -> 19602
B20: Reported total assets | C20: =IF(COUNTIFS('Actuals'!$K$6:$K$163,"visa|"&C$8&"|total_assets")=1,IF(AND(COUNTIFS('Actuals'!$K$6:$K$163,"visa|"&C$8&"|total_assets",'Actuals'!$F$6:$F$163,"<>")=1,ISNUMBER(_xlfn.XLOOKUP("visa|"&C$8&"|total_assets",'Actuals'!$K$6:$K$163,'Actuals'!$F$6:$F$163,"n.a.",0)),_xlfn.XLOOKUP("visa|"&C$8&"|total_assets",'Actuals'!$K$6:$K$163,'Actuals'!$G$6:$G$163,"n.a.",0)="USD"),_xlfn.XLOOKUP("visa|"&C$8&"|total_assets",'Actuals'!$K$6:$K$163,'Actuals'!$F$6:$F$163,"n.a.",0)/1000000,"n.a."),"n.a.") -> 82896 | D20: =IF(COUNTIFS('Actuals'!$K$6:$K$163,"visa|"&D$8&"|total_assets")=1,IF(AND(COUNTIFS('Actuals'!$K$6:$K$163,"visa|"&D$8&"|total_assets",'Actuals'!$F$6:$F$163,"<>")=1,ISNUMBER(_xlfn.XLOOKUP("visa|"&D$8&"|total_assets",'Actuals'!$K$6:$K$163,'Actuals'!$F$6:$F$163,"n.a.",0)),_xlfn.XLOOKUP("visa|"&D$8&"|total_assets",'Actuals'!$K$6:$K$163,'Actuals'!$G$6:$G$163,"n.a.",0)="USD"),_xlfn.XLOOKUP("visa|"&D$8&"|total_assets",'Actuals'!$K$6:$K$163,'Actuals'!$F$6:$F$163,"n.a.",0)/1000000,"n.a."),"n.a.") -> 85501 | E20: =IF(COUNTIFS('Actuals'!$K$6:$K$163,"visa|"&E$8&"|total_assets")=1,IF(AND(COUNTIFS('Actuals'!$K$6:$K$163,"visa|"&E$8&"|total_assets",'Actuals'!$F$6:$F$163,"<>")=1,ISNUMBER(_xlfn.XLOOKUP("visa|"&E$8&"|total_assets",'Actuals'!$K$6:$K$163,'Actuals'!$F$6:$F$163,"n.a.",0)),_xlfn.XLOOKUP("visa|"&E$8&"|total_assets",'Actuals'!$K$6:$K$163,'Actuals'!$G$6:$G$163,"n.a.",0)="USD"),_xlfn.XLOOKUP("visa|"&E$8&"|total_assets",'Actuals'!$K$6:$K$163,'Actuals'!$F$6:$F$163,"n.a.",0)/1000000,"n.a."),"n.a.") -> 90499 | F20: =IF(COUNTIFS('Actuals'!$K$6:$K$163,"visa|"&F$8&"|total_assets")=1,IF(AND(COUNTIFS('Actuals'!$K$6:$K$163,"visa|"&F$8&"|total_assets",'Actuals'!$F$6:$F$163,"<>")=1,ISNUMBER(_xlfn.XLOOKUP("visa|"&F$8&"|total_assets",'Actuals'!$K$6:$K$163,'Actuals'!$F$6:$F$163,"n.a.",0)),_xlfn.XLOOKUP("visa|"&F$8&"|total_assets",'Actuals'!$K$6:$K$163,'Actuals'!$G$6:$G$163,"n.a.",0)="USD"),_xlfn.XLOOKUP("visa|"&F$8&"|total_assets",'Actuals'!$K$6:$K$163,'Actuals'!$F$6:$F$163,"n.a.",0)/1000000,"n.a."),"n.a.") -> 94511 | G20: =IF(COUNTIFS('Actuals'!$K$6:$K$163,"visa|"&G$8&"|total_assets")=1,IF(AND(COUNTIFS('Actuals'!$K$6:$K$163,"visa|"&G$8&"|total_assets",'Actuals'!$F$6:$F$163,"<>")=1,ISNUMBER(_xlfn.XLOOKUP("visa|"&G$8&"|total_assets",'Actuals'!$K$6:$K$163,'Actuals'!$F$6:$F$163,"n.a.",0)),_xlfn.XLOOKUP("visa|"&G$8&"|total_assets",'Actuals'!$K$6:$K$163,'Actuals'!$G$6:$G$163,"n.a.",0)="USD"),_xlfn.XLOOKUP("visa|"&G$8&"|total_assets",'Actuals'!$K$6:$K$163,'Actuals'!$F$6:$F$163,"n.a.",0)/1000000,"n.a."),"n.a.") -> 99627
B21: Reported total liabilities | C21: =IF(COUNTIFS('Actuals'!$K$6:$K$163,"visa|"&C$8&"|total_liabilities")=1,IF(AND(COUNTIFS('Actuals'!$K$6:$K$163,"visa|"&C$8&"|total_liabilities",'Actuals'!$F$6:$F$163,"<>")=1,ISNUMBER(_xlfn.XLOOKUP("visa|"&C$8&"|total_liabilities",'Actuals'!$K$6:$K$163,'Actuals'!$F$6:$F$163,"n.a.",0)),_xlfn.XLOOKUP("visa|"&C$8&"|total_liabilities",'Actuals'!$K$6:$K$163,'Actuals'!$G$6:$G$163,"n.a.",0)="USD"),_xlfn.XLOOKUP("visa|"&C$8&"|total_liabilities",'Actuals'!$K$6:$K$163,'Actuals'!$F$6:$F$163,"n.a.",0)/1000000,"n.a."),"n.a.") -> 45307 | D21: =IF(COUNTIFS('Actuals'!$K$6:$K$163,"visa|"&D$8&"|total_liabilities")=1,IF(AND(COUNTIFS('Actuals'!$K$6:$K$163,"visa|"&D$8&"|total_liabilities",'Actuals'!$F$6:$F$163,"<>")=1,ISNUMBER(_xlfn.XLOOKUP("visa|"&D$8&"|total_liabilities",'Actuals'!$K$6:$K$163,'Actuals'!$F$6:$F$163,"n.a.",0)),_xlfn.XLOOKUP("visa|"&D$8&"|total_liabilities",'Actuals'!$K$6:$K$163,'Actuals'!$G$6:$G$163,"n.a.",0)="USD"),_xlfn.XLOOKUP("visa|"&D$8&"|total_liabilities",'Actuals'!$K$6:$K$163,'Actuals'!$F$6:$F$163,"n.a.",0)/1000000,"n.a."),"n.a.") -> 49920 | E21: =IF(COUNTIFS('Actuals'!$K$6:$K$163,"visa|"&E$8&"|total_liabilities")=1,IF(AND(COUNTIFS('Actuals'!$K$6:$K$163,"visa|"&E$8&"|total_liabilities",'Actuals'!$F$6:$F$163,"<>")=1,ISNUMBER(_xlfn.XLOOKUP("visa|"&E$8&"|total_liabilities",'Actuals'!$K$6:$K$163,'Actuals'!$F$6:$F$163,"n.a.",0)),_xlfn.XLOOKUP("visa|"&E$8&"|total_liabilities",'Actuals'!$K$6:$K$163,'Actuals'!$G$6:$G$163,"n.a.",0)="USD"),_xlfn.XLOOKUP("visa|"&E$8&"|total_liabilities",'Actuals'!$K$6:$K$163,'Actuals'!$F$6:$F$163,"n.a.",0)/1000000,"n.a."),"n.a.") -> 51766 | F21: =IF(COUNTIFS('Actuals'!$K$6:$K$163,"visa|"&F$8&"|total_liabilities")=1,IF(AND(COUNTIFS('Actuals'!$K$6:$K$163,"visa|"&F$8&"|total_liabilities",'Actuals'!$F$6:$F$163,"<>")=1,ISNUMBER(_xlfn.XLOOKUP("visa|"&F$8&"|total_liabilities",'Actuals'!$K$6:$K$163,'Actuals'!$F$6:$F$163,"n.a.",0)),_xlfn.XLOOKUP("visa|"&F$8&"|total_liabilities",'Actuals'!$K$6:$K$163,'Actuals'!$G$6:$G$163,"n.a.",0)="USD"),_xlfn.XLOOKUP("visa|"&F$8&"|total_liabilities",'Actuals'!$K$6:$K$163,'Actuals'!$F$6:$F$163,"n.a.",0)/1000000,"n.a."),"n.a.") -> 55374 | G21: =IF(COUNTIFS('Actuals'!$K$6:$K$163,"visa|"&G$8&"|total_liabilities")=1,IF(AND(COUNTIFS('Actuals'!$K$6:$K$163,"visa|"&G$8&"|total_liabilities",'Actuals'!$F$6:$F$163,"<>")=1,ISNUMBER(_xlfn.XLOOKUP("visa|"&G$8&"|total_liabilities",'Actuals'!$K$6:$K$163,'Actuals'!$F$6:$F$163,"n.a.",0)),_xlfn.XLOOKUP("visa|"&G$8&"|total_liabilities",'Actuals'!$K$6:$K$163,'Actuals'!$G$6:$G$163,"n.a.",0)="USD"),_xlfn.XLOOKUP("visa|"&G$8&"|total_liabilities",'Actuals'!$K$6:$K$163,'Actuals'!$F$6:$F$163,"n.a.",0)/1000000,"n.a."),"n.a.") -> 61718
B22: Reported net revenue YoY growth | C22: ="n.a." -> n.a. | D22: =IF(AND(ISNUMBER(D12),ISNUMBER(C12),C12>0),D12/C12-1,"n.a.") -> 0.2159303 | E22: =IF(AND(ISNUMBER(E12),ISNUMBER(D12),D12>0),E12/D12-1,"n.a.") -> 0.11405664 | F22: =IF(AND(ISNUMBER(F12),ISNUMBER(E12),E12>0),F12/E12-1,"n.a.") -> 0.10023581 | G22: =IF(AND(ISNUMBER(G12),ISNUMBER(F12),F12>0),G12/F12-1,"n.a.") -> 0.11339977
B23: Reported operating income YoY growth | C23: ="n.a." -> n.a. | D23: =IF(AND(ISNUMBER(D14),ISNUMBER(C14),C14>0),D14/C14-1,"n.a.") -> 0.19039484 | E23: =IF(AND(ISNUMBER(E14),ISNUMBER(D14),D14>0),E14/D14-1,"n.a.") -> 0.1162494 | F23: =IF(AND(ISNUMBER(F14),ISNUMBER(E14),E14>0),F14/E14-1,"n.a.") -> 0.12357143 | G23: =IF(AND(ISNUMBER(G14),ISNUMBER(F14),F14>0),G14/F14-1,"n.a.") -> 0.016910362
B24: Operating margin | C24: =IF(AND(ISNUMBER(C14),ISNUMBER(C12),C12>0),C14/C12,"n.a.") -> 0.65563161 | D24: =IF(AND(ISNUMBER(D14),ISNUMBER(D12),D12>0),D14/D12,"n.a.") -> 0.64186285 | E24: =IF(AND(ISNUMBER(E14),ISNUMBER(E12),E12>0),E14/E12,"n.a.") -> 0.64312621 | F24: =IF(AND(ISNUMBER(F14),ISNUMBER(F12),F12>0),F14/F12,"n.a.") -> 0.65676669 | G24: =IF(AND(ISNUMBER(G14),ISNUMBER(G12),G12>0),G14/G12,"n.a.") -> 0.59985
B25: Consolidated net margin | C25: =IF(AND(ISNUMBER(C15),ISNUMBER(C12),C12>0),C15/C12,"n.a.") -> 0.51072392 | D25: =IF(AND(ISNUMBER(D15),ISNUMBER(D12),D12>0),D15/D12,"n.a.") -> 0.51030365 | E25: =IF(AND(ISNUMBER(E15),ISNUMBER(E12),E12>0),E15/E12,"n.a.") -> 0.52898662 | F25: =IF(AND(ISNUMBER(F15),ISNUMBER(F12),F12>0),F15/F12,"n.a.") -> 0.54954629 | G25: =IF(AND(ISNUMBER(G15),ISNUMBER(G12),G12>0),G15/G12,"n.a.") -> 0.50145
B26: Operating expense ratio | C26: =IF(AND(ISNUMBER(C13),ISNUMBER(C12),C12>0),C13/C12,"n.a.") -> 0.34436839 | D26: =IF(AND(ISNUMBER(D13),ISNUMBER(D12),D12>0),D13/D12,"n.a.") -> 0.35813715 | E26: =IF(AND(ISNUMBER(E13),ISNUMBER(E12),E12>0),E13/E12,"n.a.") -> 0.35687379 | F26: =IF(AND(ISNUMBER(F13),ISNUMBER(F12),F12>0),F13/F12,"n.a.") -> 0.34323331 | G26: =IF(AND(ISNUMBER(G13),ISNUMBER(G12),G12>0),G13/G12,"n.a.") -> 0.40015
B27: OCF / consolidated net income | C27: =IF(AND(ISNUMBER(C16),ISNUMBER(C15),C15>0),C16/C15,"n.a.") -> 1.2368613 | D27: =IF(AND(ISNUMBER(D16),ISNUMBER(D15),D15>0),D16/D15,"n.a.") -> 1.2602126 | E27: =IF(AND(ISNUMBER(E16),ISNUMBER(E15),E15>0),E16/E15,"n.a.") -> 1.2015863 | F27: =IF(AND(ISNUMBER(F16),ISNUMBER(F15),F15>0),F16/F15,"n.a.") -> 1.0104847 | G27: =IF(AND(ISNUMBER(G16),ISNUMBER(G15),G15>0),G16/G15,"n.a.") -> 1.1496161
B28: Operating margin YoY change | C28: ="n.a." -> n.a. | D28: =IF(AND(ISNUMBER(D24),ISNUMBER(C24)),(D24-C24)*100,"n.a.") -> -1.3768766 | E28: =IF(AND(ISNUMBER(E24),ISNUMBER(D24)),(E24-D24)*100,"n.a.") -> 0.12633604 | F28: =IF(AND(ISNUMBER(F24),ISNUMBER(E24)),(F24-E24)*100,"n.a.") -> 1.3640481 | G28: =IF(AND(ISNUMBER(G24),ISNUMBER(F24)),(G24-F24)*100,"n.a.") -> -5.6916687
B29: Defined capital cash payments | C29: =IF(AND(ISNUMBER(IF(COUNTIFS('Actuals'!$K$6:$K$163,"visa|"&C$8&"|capital_payments_primary")=1,IF(AND(COUNTIFS('Actuals'!$K$6:$K$163,"visa|"&C$8&"|capital_payments_primary",'Actuals'!$F$6:$F$163,"<>")=1,ISNUMBER(_xlfn.XLOOKUP("visa|"&C$8&"|capital_payments_primary",'Actuals'!$K$6:$K$163,'Actuals'!$F$6:$F$163,"n.a.",0)),_xlfn.XLOOKUP("visa|"&C$8&"|capital_payments_primary",'Actuals'!$K$6:$K$163,'Actuals'!$G$6:$G$163,"n.a.",0)="USD"),_xlfn.XLOOKUP("visa|"&C$8&"|capital_payments_primary",'Actuals'!$K$6:$K$163,'Actuals'!$F$6:$F$163,"n.a.",0)/1000000,"n.a."),"n.a."))),SUM(IF(COUNTIFS('Actuals'!$K$6:$K$163,"visa|"&C$8&"|capital_payments_primary")=1,IF(AND(COUNTIFS('Actuals'!$K$6:$K$163,"visa|"&C$8&"|capital_payments_primary",'Actuals'!$F$6:$F$163,"<>")=1,ISNUMBER(_xlfn.XLOOKUP("visa|"&C$8&"|capital_payments_primary",'Actuals'!$K$6:$K$163,'Actuals'!$F$6:$F$163,"n.a.",0)),_xlfn.XLOOKUP("visa|"&C$8&"|capital_payments_primary",'Actuals'!$K$6:$K$163,'Actuals'!$G$6:$G$163,"n.a.",0)="USD"),_xlfn.XLOOKUP("visa|"&C$8&"|capital_payments_primary",'Actuals'!$K$6:$K$163,'Actuals'!$F$6:$F$163,"n.a.",0)/1000000,"n.a."),"n.a.")),"n.a.") -> 705 | D29: =IF(AND(ISNUMBER(IF(COUNTIFS('Actuals'!$K$6:$K$163,"visa|"&D$8&"|capital_payments_primary")=1,IF(AND(COUNTIFS('Actuals'!$K$6:$K$163,"visa|"&D$8&"|capital_payments_primary",'Actuals'!$F$6:$F$163,"<>")=1,ISNUMBER(_xlfn.XLOOKUP("visa|"&D$8&"|capital_payments_primary",'Actuals'!$K$6:$K$163,'Actuals'!$F$6:$F$163,"n.a.",0)),_xlfn.XLOOKUP("visa|"&D$8&"|capital_payments_primary",'Actuals'!$K$6:$K$163,'Actuals'!$G$6:$G$163,"n.a.",0)="USD"),_xlfn.XLOOKUP("visa|"&D$8&"|capital_payments_primary",'Actuals'!$K$6:$K$163,'Actuals'!$F$6:$F$163,"n.a.",0)/1000000,"n.a."),"n.a."))),SUM(IF(COUNTIFS('Actuals'!$K$6:$K$163,"visa|"&D$8&"|capital_payments_primary")=1,IF(AND(COUNTIFS('Actuals'!$K$6:$K$163,"visa|"&D$8&"|capital_payments_primary",'Actuals'!$F$6:$F$163,"<>")=1,ISNUMBER(_xlfn.XLOOKUP("visa|"&D$8&"|capital_payments_primary",'Actuals'!$K$6:$K$163,'Actuals'!$F$6:$F$163,"n.a.",0)),_xlfn.XLOOKUP("visa|"&D$8&"|capital_payments_primary",'Actuals'!$K$6:$K$163,'Actuals'!$G$6:$G$163,"n.a.",0)="USD"),_xlfn.XLOOKUP("visa|"&D$8&"|capital_payments_primary",'Actuals'!$K$6:$K$163,'Actuals'!$F$6:$F$163,"n.a.",0)/1000000,"n.a."),"n.a.")),"n.a.") -> 970 | E29: =IF(AND(ISNUMBER(IF(COUNTIFS('Actuals'!$K$6:$K$163,"visa|"&E$8&"|capital_payments_primary")=1,IF(AND(COUNTIFS('Actuals'!$K$6:$K$163,"visa|"&E$8&"|capital_payments_primary",'Actuals'!$F$6:$F$163,"<>")=1,ISNUMBER(_xlfn.XLOOKUP("visa|"&E$8&"|capital_payments_primary",'Actuals'!$K$6:$K$163,'Actuals'!$F$6:$F$163,"n.a.",0)),_xlfn.XLOOKUP("visa|"&E$8&"|capital_payments_primary",'Actuals'!$K$6:$K$163,'Actuals'!$G$6:$G$163,"n.a.",0)="USD"),_xlfn.XLOOKUP("visa|"&E$8&"|capital_payments_primary",'Actuals'!$K$6:$K$163,'Actuals'!$F$6:$F$163,"n.a.",0)/1000000,"n.a."),"n.a."))),SUM(IF(COUNTIFS('Actuals'!$K$6:$K$163,"visa|"&E$8&"|capital_payments_primary")=1,IF(AND(COUNTIFS('Actuals'!$K$6:$K$163,"visa|"&E$8&"|capital_payments_primary",'Actuals'!$F$6:$F$163,"<>")=1,ISNUMBER(_xlfn.XLOOKUP("visa|"&E$8&"|capital_payments_primary",'Actuals'!$K$6:$K$163,'Actuals'!$F$6:$F$163,"n.a.",0)),_xlfn.XLOOKUP("visa|"&E$8&"|capital_payments_primary",'Actuals'!$K$6:$K$163,'Actuals'!$G$6:$G$163,"n.a.",0)="USD"),_xlfn.XLOOKUP("visa|"&E$8&"|capital_payments_primary",'Actuals'!$K$6:$K$163,'Actuals'!$F$6:$F$163,"n.a.",0)/1000000,"n.a."),"n.a.")),"n.a.") -> 1059 | F29: =IF(AND(ISNUMBER(IF(COUNTIFS('Actuals'!$K$6:$K$163,"visa|"&F$8&"|capital_payments_primary")=1,IF(AND(COUNTIFS('Actuals'!$K$6:$K$163,"visa|"&F$8&"|capital_payments_primary",'Actuals'!$F$6:$F$163,"<>")=1,ISNUMBER(_xlfn.XLOOKUP("visa|"&F$8&"|capital_payments_primary",'Actuals'!$K$6:$K$163,'Actuals'!$F$6:$F$163,"n.a.",0)),_xlfn.XLOOKUP("visa|"&F$8&"|capital_payments_primary",'Actuals'!$K$6:$K$163,'Actuals'!$G$6:$G$163,"n.a.",0)="USD"),_xlfn.XLOOKUP("visa|"&F$8&"|capital_payments_primary",'Actuals'!$K$6:$K$163,'Actuals'!$F$6:$F$163,"n.a.",0)/1000000,"n.a."),"n.a."))),SUM(IF(COUNTIFS('Actuals'!$K$6:$K$163,"visa|"&F$8&"|capital_payments_primary")=1,IF(AND(COUNTIFS('Actuals'!$K$6:$K$163,"visa|"&F$8&"|capital_payments_primary",'Actuals'!$F$6:$F$163,"<>")=1,ISNUMBER(_xlfn.XLOOKUP("visa|"&F$8&"|capital_payments_primary",'Actuals'!$K$6:$K$163,'Actuals'!$F$6:$F$163,"n.a.",0)),_xlfn.XLOOKUP("visa|"&F$8&"|capital_payments_primary",'Actuals'!$K$6:$K$163,'Actuals'!$G$6:$G$163,"n.a.",0)="USD"),_xlfn.XLOOKUP("visa|"&F$8&"|capital_payments_primary",'Actuals'!$K$6:$K$163,'Actuals'!$F$6:$F$163,"n.a.",0)/1000000,"n.a."),"n.a.")),"n.a.") -> 1257 | G29: =IF(AND(ISNUMBER(IF(COUNTIFS('Actuals'!$K$6:$K$163,"visa|"&G$8&"|capital_payments_primary")=1,IF(AND(COUNTIFS('Actuals'!$K$6:$K$163,"visa|"&G$8&"|capital_payments_primary",'Actuals'!$F$6:$F$163,"<>")=1,ISNUMBER(_xlfn.XLOOKUP("visa|"&G$8&"|capital_payments_primary",'Actuals'!$K$6:$K$163,'Actuals'!$F$6:$F$163,"n.a.",0)),_xlfn.XLOOKUP("visa|"&G$8&"|capital_payments_primary",'Actuals'!$K$6:$K$163,'Actuals'!$G$6:$G$163,"n.a.",0)="USD"),_xlfn.XLOOKUP("visa|"&G$8&"|capital_payments_primary",'Actuals'!$K$6:$K$163,'Actuals'!$F$6:$F$163,"n.a.",0)/1000000,"n.a."),"n.a."))),SUM(IF(COUNTIFS('Actuals'!$K$6:$K$163,"visa|"&G$8&"|capital_payments_primary")=1,IF(AND(COUNTIFS('Actuals'!$K$6:$K$163,"visa|"&G$8&"|capital_payments_primary",'Actuals'!$F$6:$F$163,"<>")=1,ISNUMBER(_xlfn.XLOOKUP("visa|"&G$8&"|capital_payments_primary",'Actuals'!$K$6:$K$163,'Actuals'!$F$6:$F$163,"n.a.",0)),_xlfn.XLOOKUP("visa|"&G$8&"|capital_payments_primary",'Actuals'!$K$6:$K$163,'Actuals'!$G$6:$G$163,"n.a.",0)="USD"),_xlfn.XLOOKUP("visa|"&G$8&"|capital_payments_primary",'Actuals'!$K$6:$K$163,'Actuals'!$F$6:$F$163,"n.a.",0)/1000000,"n.a."),"n.a.")),"n.a.") -> 1482
B30: OCF less defined capital payments | C30: =IF(AND(ISNUMBER(C16),ISNUMBER(C29)),C16-C29,"n.a.") -> 14522 | D30: =IF(AND(ISNUMBER(D16),ISNUMBER(D29)),D16-D29,"n.a.") -> 17879 | E30: =IF(AND(ISNUMBER(E16),ISNUMBER(E29)),E16-E29,"n.a.") -> 19696 | F30: =IF(AND(ISNUMBER(F16),ISNUMBER(F29)),F16-F29,"n.a.") -> 18693 | G30: =IF(AND(ISNUMBER(G16),ISNUMBER(G29)),G16-G29,"n.a.") -> 21577
B31: FCF proxy / net revenue | C31: =IF(AND(ISNUMBER(C30),ISNUMBER(C12),C12>0),C30/C12,"n.a.") -> 0.60244762 | D31: =IF(AND(ISNUMBER(D30),ISNUMBER(D12),D12>0),D30/D12,"n.a.") -> 0.60999659 | E31: =IF(AND(ISNUMBER(E30),ISNUMBER(E12),E12>0),E30/E12,"n.a.") -> 0.60319113 | F31: =IF(AND(ISNUMBER(F30),ISNUMBER(F12),F12>0),F30/F12,"n.a.") -> 0.52031955 | G31: =IF(AND(ISNUMBER(G30),ISNUMBER(G12),G12>0),G30/G12,"n.a.") -> 0.539425
B32: Selected debt carrying total | C32: =IF(AND(ISNUMBER(C18),ISNUMBER(C19)),SUM(C18,C19),"n.a.") -> 20977 | D32: =IF(AND(ISNUMBER(D18),ISNUMBER(D19)),SUM(D18,D19),"n.a.") -> 22450 | E32: =IF(AND(ISNUMBER(E18),ISNUMBER(E19)),SUM(E18,E19),"n.a.") -> 20463 | F32: =IF(AND(ISNUMBER(F18),ISNUMBER(F19)),SUM(F18,F19),"n.a.") -> 20836 | G32: =IF(AND(ISNUMBER(G18),ISNUMBER(G19)),SUM(G18,G19),"n.a.") -> 25171
B33: Selected debt less cash proxy | C33: =IF(AND(ISNUMBER(C32),ISNUMBER(C17)),C32-C17,"n.a.") -> 4490 | D33: =IF(AND(ISNUMBER(D32),ISNUMBER(D17)),D32-D17,"n.a.") -> 6761 | E33: =IF(AND(ISNUMBER(E32),ISNUMBER(E17)),E32-E17,"n.a.") -> 4177 | F33: =IF(AND(ISNUMBER(F32),ISNUMBER(F17)),F32-F17,"n.a.") -> 8861 | G33: =IF(AND(ISNUMBER(G32),ISNUMBER(G17)),G32-G17,"n.a.") -> 8007
B34: Selected debt / total assets | C34: =IF(AND(ISNUMBER(C32),ISNUMBER(C20),C20>0),C32/C20,"n.a.") -> 0.25305202 | D34: =IF(AND(ISNUMBER(D32),ISNUMBER(D20),D20>0),D32/D20,"n.a.") -> 0.26257003 | E34: =IF(AND(ISNUMBER(E32),ISNUMBER(E20),E20>0),E32/E20,"n.a.") -> 0.226113 | F34: =IF(AND(ISNUMBER(F32),ISNUMBER(F20),F20>0),F32/F20,"n.a.") -> 0.22046111 | G34: =IF(AND(ISNUMBER(G32),ISNUMBER(G20),G20>0),G32/G20,"n.a.") -> 0.25265239
B35: Total liabilities / total assets | C35: =IF(AND(ISNUMBER(C21),ISNUMBER(C20),C20>0),C21/C20,"n.a.") -> 0.54655231 | D35: =IF(AND(ISNUMBER(D21),ISNUMBER(D20),D20>0),D21/D20,"n.a.") -> 0.58385282 | E35: =IF(AND(ISNUMBER(E21),ISNUMBER(E20),E20>0),E21/E20,"n.a.") -> 0.57200632 | F35: =IF(AND(ISNUMBER(F21),ISNUMBER(F20),F20>0),F21/F20,"n.a.") -> 0.58590005 | G35: =IF(AND(ISNUMBER(G21),ISNUMBER(G20),G20>0),G21/G20,"n.a.") -> 0.6194907
B36: Cash equivalents / selected debt | C36: =IF(AND(ISNUMBER(C17),ISNUMBER(C32),C32>0),C17/C32,"n.a.") -> 0.78595605 | D36: =IF(AND(ISNUMBER(D17),ISNUMBER(D32),D32>0),D17/D32,"n.a.") -> 0.69884187 | E36: =IF(AND(ISNUMBER(E17),ISNUMBER(E32),E32>0),E17/E32,"n.a.") -> 0.79587548 | F36: =IF(AND(ISNUMBER(F17),ISNUMBER(F32),F32>0),F17/F32,"n.a.") -> 0.57472644 | G36: =IF(AND(ISNUMBER(G17),ISNUMBER(G32),G32>0),G17/G32,"n.a.") -> 0.68189583
B38: First-year changes are n.a.: no verified FY2020 input.
B40: Visa year end Sep30; Mastercard Dec31. No calendar adjustment.
B45: Mastercard reported fiscal years
B46: Fiscal year | C46: 2021 | D46: 2022 | E46: 2023 | F46: 2024 | G46: 2025
B47: Period start | C47: 2021-01-01T00:00:00.000Z | D47: 2022-01-01T00:00:00.000Z | E47: 2023-01-01T00:00:00.000Z | F47: 2024-01-01T00:00:00.000Z | G47: 2025-01-01T00:00:00.000Z
B48: Period end | C48: 2021-12-31T00:00:00.000Z | D48: 2022-12-31T00:00:00.000Z | E48: 2023-12-31T00:00:00.000Z | F48: 2024-12-31T00:00:00.000Z | G48: 2025-12-31T00:00:00.000Z
B50: Reported net revenue | C50: =IF(COUNTIFS('Actuals'!$K$6:$K$163,"mastercard|"&C$46&"|net_revenue")=1,IF(AND(COUNTIFS('Actuals'!$K$6:$K$163,"mastercard|"&C$46&"|net_revenue",'Actuals'!$F$6:$F$163,"<>")=1,ISNUMBER(_xlfn.XLOOKUP("mastercard|"&C$46&"|net_revenue",'Actuals'!$K$6:$K$163,'Actuals'!$F$6:$F$163,"n.a.",0)),_xlfn.XLOOKUP("mastercard|"&C$46&"|net_revenue",'Actuals'!$K$6:$K$163,'Actuals'!$G$6:$G$163,"n.a.",0)="USD"),_xlfn.XLOOKUP("mastercard|"&C$46&"|net_revenue",'Actuals'!$K$6:$K$163,'Actuals'!$F$6:$F$163,"n.a.",0)/1000000,"n.a."),"n.a.") -> 18884 | D50: =IF(COUNTIFS('Actuals'!$K$6:$K$163,"mastercard|"&D$46&"|net_revenue")=1,IF(AND(COUNTIFS('Actuals'!$K$6:$K$163,"mastercard|"&D$46&"|net_revenue",'Actuals'!$F$6:$F$163,"<>")=1,ISNUMBER(_xlfn.XLOOKUP("mastercard|"&D$46&"|net_revenue",'Actuals'!$K$6:$K$163,'Actuals'!$F$6:$F$163,"n.a.",0)),_xlfn.XLOOKUP("mastercard|"&D$46&"|net_revenue",'Actuals'!$K$6:$K$163,'Actuals'!$G$6:$G$163,"n.a.",0)="USD"),_xlfn.XLOOKUP("mastercard|"&D$46&"|net_revenue",'Actuals'!$K$6:$K$163,'Actuals'!$F$6:$F$163,"n.a.",0)/1000000,"n.a."),"n.a.") -> 22237 | E50: =IF(COUNTIFS('Actuals'!$K$6:$K$163,"mastercard|"&E$46&"|net_revenue")=1,IF(AND(COUNTIFS('Actuals'!$K$6:$K$163,"mastercard|"&E$46&"|net_revenue",'Actuals'!$F$6:$F$163,"<>")=1,ISNUMBER(_xlfn.XLOOKUP("mastercard|"&E$46&"|net_revenue",'Actuals'!$K$6:$K$163,'Actuals'!$F$6:$F$163,"n.a.",0)),_xlfn.XLOOKUP("mastercard|"&E$46&"|net_revenue",'Actuals'!$K$6:$K$163,'Actuals'!$G$6:$G$163,"n.a.",0)="USD"),_xlfn.XLOOKUP("mastercard|"&E$46&"|net_revenue",'Actuals'!$K$6:$K$163,'Actuals'!$F$6:$F$163,"n.a.",0)/1000000,"n.a."),"n.a.") -> 25098 | F50: =IF(COUNTIFS('Actuals'!$K$6:$K$163,"mastercard|"&F$46&"|net_revenue")=1,IF(AND(COUNTIFS('Actuals'!$K$6:$K$163,"mastercard|"&F$46&"|net_revenue",'Actuals'!$F$6:$F$163,"<>")=1,ISNUMBER(_xlfn.XLOOKUP("mastercard|"&F$46&"|net_revenue",'Actuals'!$K$6:$K$163,'Actuals'!$F$6:$F$163,"n.a.",0)),_xlfn.XLOOKUP("mastercard|"&F$46&"|net_revenue",'Actuals'!$K$6:$K$163,'Actuals'!$G$6:$G$163,"n.a.",0)="USD"),_xlfn.XLOOKUP("mastercard|"&F$46&"|net_revenue",'Actuals'!$K$6:$K$163,'Actuals'!$F$6:$F$163,"n.a.",0)/1000000,"n.a."),"n.a.") -> 28167 | G50: =IF(COUNTIFS('Actuals'!$K$6:$K$163,"mastercard|"&G$46&"|net_revenue")=1,IF(AND(COUNTIFS('Actuals'!$K$6:$K$163,"mastercard|"&G$46&"|net_revenue",'Actuals'!$F$6:$F$163,"<>")=1,ISNUMBER(_xlfn.XLOOKUP("mastercard|"&G$46&"|net_revenue",'Actuals'!$K$6:$K$163,'Actuals'!$F$6:$F$163,"n.a.",0)),_xlfn.XLOOKUP("mastercard|"&G$46&"|net_revenue",'Actuals'!$K$6:$K$163,'Actuals'!$G$6:$G$163,"n.a.",0)="USD"),_xlfn.XLOOKUP("mastercard|"&G$46&"|net_revenue",'Actuals'!$K$6:$K$163,'Actuals'!$F$6:$F$163,"n.a.",0)/1000000,"n.a."),"n.a.") -> 32791
B51: Reported operating expenses | C51: =IF(COUNTIFS('Actuals'!$K$6:$K$163,"mastercard|"&C$46&"|operating_expenses")=1,IF(AND(COUNTIFS('Actuals'!$K$6:$K$163,"mastercard|"&C$46&"|operating_expenses",'Actuals'!$F$6:$F$163,"<>")=1,ISNUMBER(_xlfn.XLOOKUP("mastercard|"&C$46&"|operating_expenses",'Actuals'!$K$6:$K$163,'Actuals'!$F$6:$F$163,"n.a.",0)),_xlfn.XLOOKUP("mastercard|"&C$46&"|operating_expenses",'Actuals'!$K$6:$K$163,'Actuals'!$G$6:$G$163,"n.a.",0)="USD"),_xlfn.XLOOKUP("mastercard|"&C$46&"|operating_expenses",'Actuals'!$K$6:$K$163,'Actuals'!$F$6:$F$163,"n.a.",0)/1000000,"n.a."),"n.a.") -> 8802 | D51: =IF(COUNTIFS('Actuals'!$K$6:$K$163,"mastercard|"&D$46&"|operating_expenses")=1,IF(AND(COUNTIFS('Actuals'!$K$6:$K$163,"mastercard|"&D$46&"|operating_expenses",'Actuals'!$F$6:$F$163,"<>")=1,ISNUMBER(_xlfn.XLOOKUP("mastercard|"&D$46&"|operating_expenses",'Actuals'!$K$6:$K$163,'Actuals'!$F$6:$F$163,"n.a.",0)),_xlfn.XLOOKUP("mastercard|"&D$46&"|operating_expenses",'Actuals'!$K$6:$K$163,'Actuals'!$G$6:$G$163,"n.a.",0)="USD"),_xlfn.XLOOKUP("mastercard|"&D$46&"|operating_expenses",'Actuals'!$K$6:$K$163,'Actuals'!$F$6:$F$163,"n.a.",0)/1000000,"n.a."),"n.a.") -> 9973 | E51: =IF(COUNTIFS('Actuals'!$K$6:$K$163,"mastercard|"&E$46&"|operating_expenses")=1,IF(AND(COUNTIFS('Actuals'!$K$6:$K$163,"mastercard|"&E$46&"|operating_expenses",'Actuals'!$F$6:$F$163,"<>")=1,ISNUMBER(_xlfn.XLOOKUP("mastercard|"&E$46&"|operating_expenses",'Actuals'!$K$6:$K$163,'Actuals'!$F$6:$F$163,"n.a.",0)),_xlfn.XLOOKUP("mastercard|"&E$46&"|operating_expenses",'Actuals'!$K$6:$K$163,'Actuals'!$G$6:$G$163,"n.a.",0)="USD"),_xlfn.XLOOKUP("mastercard|"&E$46&"|operating_expenses",'Actuals'!$K$6:$K$163,'Actuals'!$F$6:$F$163,"n.a.",0)/1000000,"n.a."),"n.a.") -> 11090 | F51: =IF(COUNTIFS('Actuals'!$K$6:$K$163,"mastercard|"&F$46&"|operating_expenses")=1,IF(AND(COUNTIFS('Actuals'!$K$6:$K$163,"mastercard|"&F$46&"|operating_expenses",'Actuals'!$F$6:$F$163,"<>")=1,ISNUMBER(_xlfn.XLOOKUP("mastercard|"&F$46&"|operating_expenses",'Actuals'!$K$6:$K$163,'Actuals'!$F$6:$F$163,"n.a.",0)),_xlfn.XLOOKUP("mastercard|"&F$46&"|operating_expenses",'Actuals'!$K$6:$K$163,'Actuals'!$G$6:$G$163,"n.a.",0)="USD"),_xlfn.XLOOKUP("mastercard|"&F$46&"|operating_expenses",'Actuals'!$K$6:$K$163,'Actuals'!$F$6:$F$163,"n.a.",0)/1000000,"n.a."),"n.a.") -> 12585 | G51: =IF(COUNTIFS('Actuals'!$K$6:$K$163,"mastercard|"&G$46&"|operating_expenses")=1,IF(AND(COUNTIFS('Actuals'!$K$6:$K$163,"mastercard|"&G$46&"|operating_expenses",'Actuals'!$F$6:$F$163,"<>")=1,ISNUMBER(_xlfn.XLOOKUP("mastercard|"&G$46&"|operating_expenses",'Actuals'!$K$6:$K$163,'Actuals'!$F$6:$F$163,"n.a.",0)),_xlfn.XLOOKUP("mastercard|"&G$46&"|operating_expenses",'Actuals'!$K$6:$K$163,'Actuals'!$G$6:$G$163,"n.a.",0)="USD"),_xlfn.XLOOKUP("mastercard|"&G$46&"|operating_expenses",'Actuals'!$K$6:$K$163,'Actuals'!$F$6:$F$163,"n.a.",0)/1000000,"n.a."),"n.a.") -> 13894
...

Sheet Actuals
A1: Reviewed statement inputs
A2: Amounts in original USD. Source reporting units were normalized before this workbook.
A3: Frozen FY2021–2025 evidence. Edit only the amber assumptions on Scenario.
A5: Company | B5: Fiscal year | C5: Item | D5: Period start | E5: Period end | F5: Amount (USD) | G5: Unit | H5: IR PDF page | I5: Filing accession | J5: Original source | K5: Lookup key | M5: Original PDF URL
A6: visa | B6: 2021 | C6: net_revenue | D6: 2020-10-01T00:00:00.000Z | E6: 2021-09-30T00:00:00.000Z | F6: 24105000000 | G6: USD | H6: 67 | I6: 0001403161-23-000099 | J6: Visa FY2023 annual report, PDF p67 | K6: =A6&"|"&B6&"|"&C6 -> visa|2021|net_revenue | M6: =_xlfn.XLOOKUP(I6,$I$169:$I$174,$M$169:$M$174,"n.a.",0) -> https://s29.q4cdn.com/385744025/files/doc_downloads/2023/Visa-Inc-Fiscal-2023-Annual-Report.pdf
A7: visa | B7: 2021 | C7: operating_expenses | D7: 2020-10-01T00:00:00.000Z | E7: 2021-09-30T00:00:00.000Z | F7: 8301000000 | G7: USD | H7: 67 | I7: 0001403161-23-000099 | J7: Visa FY2023 annual report, PDF p67 | K7: =A7&"|"&B7&"|"&C7 -> visa|2021|operating_expenses | M7: =_xlfn.XLOOKUP(I7,$I$169:$I$174,$M$169:$M$174,"n.a.",0) -> https://s29.q4cdn.com/385744025/files/doc_downloads/2023/Visa-Inc-Fiscal-2023-Annual-Report.pdf
A8: visa | B8: 2021 | C8: operating_income | D8: 2020-10-01T00:00:00.000Z | E8: 2021-09-30T00:00:00.000Z | F8: 15804000000 | G8: USD | H8: 67 | I8: 0001403161-23-000099 | J8: Visa FY2023 annual report, PDF p67 | K8: =A8&"|"&B8&"|"&C8 -> visa|2021|operating_income | M8: =_xlfn.XLOOKUP(I8,$I$169:$I$174,$M$169:$M$174,"n.a.",0) -> https://s29.q4cdn.com/385744025/files/doc_downloads/2023/Visa-Inc-Fiscal-2023-Annual-Report.pdf
A9: visa | B9: 2021 | C9: pretax_income | D9: 2020-10-01T00:00:00.000Z | E9: 2021-09-30T00:00:00.000Z | F9: 16063000000 | G9: USD | H9: 67 | I9: 0001403161-23-000099 | J9: Visa FY2023 annual report, PDF p67 | K9: =A9&"|"&B9&"|"&C9 -> visa|2021|pretax_income | M9: =_xlfn.XLOOKUP(I9,$I$169:$I$174,$M$169:$M$174,"n.a.",0) -> https://s29.q4cdn.com/385744025/files/doc_downloads/2023/Visa-Inc-Fiscal-2023-Annual-Report.pdf
A10: visa | B10: 2021 | C10: income_tax | D10: 2020-10-01T00:00:00.000Z | E10: 2021-09-30T00:00:00.000Z | F10: 3752000000 | G10: USD | H10: 67 | I10: 0001403161-23-000099 | J10: Visa FY2023 annual report, PDF p67 | K10: =A10&"|"&B10&"|"&C10 -> visa|2021|income_tax | M10: =_xlfn.XLOOKUP(I10,$I$169:$I$174,$M$169:$M$174,"n.a.",0) -> https://s29.q4cdn.com/385744025/files/doc_downloads/2023/Visa-Inc-Fiscal-2023-Annual-Report.pdf
A11: visa | B11: 2021 | C11: net_income | D11: 2020-10-01T00:00:00.000Z | E11: 2021-09-30T00:00:00.000Z | F11: 12311000000 | G11: USD | H11: 67 | I11: 0001403161-23-000099 | J11: Visa FY2023 annual report, PDF p67 | K11: =A11&"|"&B11&"|"&C11 -> visa|2021|net_income | M11: =_xlfn.XLOOKUP(I11,$I$169:$I$174,$M$169:$M$174,"n.a.",0) -> https://s29.q4cdn.com/385744025/files/doc_downloads/2023/Visa-Inc-Fiscal-2023-Annual-Report.pdf
A12: visa | B12: 2021 | C12: operating_cash_flow | D12: 2020-10-01T00:00:00.000Z | E12: 2021-09-30T00:00:00.000Z | F12: 15227000000 | G12: USD | H12: 72 | I12: 0001403161-23-000099 | J12: Visa FY2023 annual report, PDF p72 | K12: =A12&"|"&B12&"|"&C12 -> visa|2021|operating_cash_flow | M12: =_xlfn.XLOOKUP(I12,$I$169:$I$174,$M$169:$M$174,"n.a.",0) -> https://s29.q4cdn.com/385744025/files/doc_downloads/2023/Visa-Inc-Fiscal-2023-Annual-Report.pdf
A13: visa | B13: 2021 | C13: capital_payments_primary | D13: 2020-10-01T00:00:00.000Z | E13: 2021-09-30T00:00:00.000Z | F13: 705000000 | G13: USD | H13: 72 | I13: 0001403161-23-000099 | J13: Visa FY2023 annual report, PDF p72 | K13: =A13&"|"&B13&"|"&C13 -> visa|2021|capital_payments_primary | M13: =_xlfn.XLOOKUP(I13,$I$169:$I$174,$M$169:$M$174,"n.a.",0) -> https://s29.q4cdn.com/385744025/files/doc_downloads/2023/Visa-Inc-Fiscal-2023-Annual-Report.pdf
A14: visa | B14: 2021 | C14: cash_and_cash_equivalents | E14: 2021-09-30T00:00:00.000Z | F14: 16487000000 | G14: USD | H14: 66 | I14: 0001403161-21-000060 | J14: Visa FY2021 annual report, PDF p66 | K14: =A14&"|"&B14&"|"&C14 -> visa|2021|cash_and_cash_equivalents | M14: =_xlfn.XLOOKUP(I14,$I$169:$I$174,$M$169:$M$174,"n.a.",0) -> https://s29.q4cdn.com/385744025/files/doc_downloads/Visa-Inc_-Fiscal-2021-Annual-Report.pdf
A15: visa | B15: 2021 | C15: current_debt | E15: 2021-09-30T00:00:00.000Z | F15: 999000000 | G15: USD | H15: 66 | I15: 0001403161-21-000060 | J15: Visa FY2021 annual report, PDF p66 | K15: =A15&"|"&B15&"|"&C15 -> visa|2021|current_debt | M15: =_xlfn.XLOOKUP(I15,$I$169:$I$174,$M$169:$M$174,"n.a.",0) -> https://s29.q4cdn.com/385744025/files/doc_downloads/Visa-Inc_-Fiscal-2021-Annual-Report.pdf
A16: visa | B16: 2021 | C16: noncurrent_debt | E16: 2021-09-30T00:00:00.000Z | F16: 19978000000 | G16: USD | H16: 66 | I16: 0001403161-21-000060 | J16: Visa FY2021 annual report, PDF p66 | K16: =A16&"|"&B16&"|"&C16 -> visa|2021|noncurrent_debt | M16: =_xlfn.XLOOKUP(I16,$I$169:$I$174,$M$169:$M$174,"n.a.",0) -> https://s29.q4cdn.com/385744025/files/doc_downloads/Visa-Inc_-Fiscal-2021-Annual-Report.pdf
A17: visa | B17: 2021 | C17: total_assets | E17: 2021-09-30T00:00:00.000Z | F17: 82896000000 | G17: USD | H17: 66 | I17: 0001403161-21-000060 | J17: Visa FY2021 annual report, PDF p66 | K17: =A17&"|"&B17&"|"&C17 -> visa|2021|total_assets | M17: =_xlfn.XLOOKUP(I17,$I$169:$I$174,$M$169:$M$174,"n.a.",0) -> https://s29.q4cdn.com/385744025/files/doc_downloads/Visa-Inc_-Fiscal-2021-Annual-Report.pdf
A18: visa | B18: 2021 | C18: total_liabilities | E18: 2021-09-30T00:00:00.000Z | F18: 45307000000 | G18: USD | H18: 66 | I18: 0001403161-21-000060 | J18: Visa FY2021 annual report, PDF p66 | K18: =A18&"|"&B18&"|"&C18 -> visa|2021|total_liabilities | M18: =_xlfn.XLOOKUP(I18,$I$169:$I$174,$M$169:$M$174,"n.a.",0) -> https://s29.q4cdn.com/385744025/files/doc_downloads/Visa-Inc_-Fiscal-2021-Annual-Report.pdf
A19: visa | B19: 2021 | C19: total_equity | E19: 2021-09-30T00:00:00.000Z | F19: 37589000000 | G19: USD | H19: 66 | I19: 0001403161-21-000060 | J19: Visa FY2021 annual report, PDF p66 | K19: =A19&"|"&B19&"|"&C19 -> visa|2021|total_equity | M19: =_xlfn.XLOOKUP(I19,$I$169:$I$174,$M$169:$M$174,"n.a.",0) -> https://s29.q4cdn.com/385744025/files/doc_downloads/Visa-Inc_-Fiscal-2021-Annual-Report.pdf
A20: visa | B20: 2021 | C20: cash_flow_total_end | E20: 2021-09-30T00:00:00.000Z | F20: 19799000000 | G20: USD | H20: 72 | I20: 0001403161-23-000099 | J20: Visa FY2023 annual report, PDF p72 | K20: =A20&"|"&B20&"|"&C20 -> visa|2021|cash_flow_total_end | M20: =_xlfn.XLOOKUP(I20,$I$169:$I$174,$M$169:$M$174,"n.a.",0) -> https://s29.q4cdn.com/385744025/files/doc_downloads/2023/Visa-Inc-Fiscal-2023-Annual-Report.pdf
A21: visa | B21: 2022 | C21: net_revenue | D21: 2021-10-01T00:00:00.000Z | E21: 2022-09-30T00:00:00.000Z | F21: 29310000000 | G21: USD | H21: 67 | I21: 0001403161-23-000099 | J21: Visa FY2023 annual report, PDF p67 | K21: =A21&"|"&B21&"|"&C21 -> visa|2022|net_revenue | M21: =_xlfn.XLOOKUP(I21,$I$169:$I$174,$M$169:$M$174,"n.a.",0) -> https://s29.q4cdn.com/385744025/files/doc_downloads/2023/Visa-Inc-Fiscal-2023-Annual-Report.pdf
A22: visa | B22: 2022 | C22: operating_expenses | D22: 2021-10-01T00:00:00.000Z | E22: 2022-09-30T00:00:00.000Z | F22: 10497000000 | G22: USD | H22: 67 | I22: 0001403161-23-000099 | J22: Visa FY2023 annual report, PDF p67 | K22: =A22&"|"&B22&"|"&C22 -> visa|2022|operating_expenses | M22: =_xlfn.XLOOKUP(I22,$I$169:$I$174,$M$169:$M$174,"n.a.",0) -> https://s29.q4cdn.com/385744025/files/doc_downloads/2023/Visa-Inc-Fiscal-2023-Annual-Report.pdf
A23: visa | B23: 2022 | C23: operating_income | D23: 2021-10-01T00:00:00.000Z | E23: 2022-09-30T00:00:00.000Z | F23: 18813000000 | G23: USD | H23: 67 | I23: 0001403161-23-000099 | J23: Visa FY2023 annual report, PDF p67 | K23: =A23&"|"&B23&"|"&C23 -> visa|2022|operating_income | M23: =_xlfn.XLOOKUP(I23,$I$169:$I$174,$M$169:$M$174,"n.a.",0) -> https://s29.q4cdn.com/385744025/files/doc_downloads/2023/Visa-Inc-Fiscal-2023-Annual-Report.pdf
A24: visa | B24: 2022 | C24: pretax_income | D24: 2021-10-01T00:00:00.000Z | E24: 2022-09-30T00:00:00.000Z | F24: 18136000000 | G24: USD | H24: 67 | I24: 0001403161-23-000099 | J24: Visa FY2023 annual report, PDF p67 | K24: =A24&"|"&B24&"|"&C24 -> visa|2022|pretax_income | M24: =_xlfn.XLOOKUP(I24,$I$169:$I$174,$M$169:$M$174,"n.a.",0) -> https://s29.q4cdn.com/385744025/files/doc_downloads/2023/Visa-Inc-Fiscal-2023-Annual-Report.pdf
A25: visa | B25: 2022 | C25: income_tax | D25: 2021-10-01T00:00:00.000Z | E25: 2022-09-30T00:00:00.000Z | F25: 3179000000 | G25: USD | H25: 67 | I25: 0001403161-23-000099 | J25: Visa FY2023 annual report, PDF p67 | K25: =A25&"|"&B25&"|"&C25 -> visa|2022|income_tax | M25: =_xlfn.XLOOKUP(I25,$I$169:$I$174,$M$169:$M$174,"n.a.",0) -> https://s29.q4cdn.com/385744025/files/doc_downloads/2023/Visa-Inc-Fiscal-2023-Annual-Report.pdf
A26: visa | B26: 2022 | C26: net_income | D26: 2021-10-01T00:00:00.000Z | E26: 2022-09-30T00:00:00.000Z | F26: 14957000000 | G26: USD | H26: 67 | I26: 0001403161-23-000099 | J26: Visa FY2023 annual report, PDF p67 | K26: =A26&"|"&B26&"|"&C26 -> visa|2022|net_income | M26: =_xlfn.XLOOKUP(I26,$I$169:$I$174,$M$169:$M$174,"n.a.",0) -> https://s29.q4cdn.com/385744025/files/doc_downloads/2023/Visa-Inc-Fiscal-2023-Annual-Report.pdf
